core.exception.ArrayIndexError@d/main.d(3): index [15206] is out of bounds for array of length 1000
----------------
??:? onArrayIndexError [0x5f76f9079f82]
??:? _d_arraybounds_indexp [0x5f76f90711cf]
d/main.d:3 int main.dangerous(int[], int) [0x5f76f906f8f8]
d/main.d:4 int main.foo(int[], int) [0x5f76f906f92e]
d/main.d:5 int main.foo1(int[], int) [0x5f76f906f959]
d/main.d:6 int main.foo2(int[], int) [0x5f76f906f984]
d/main.d:7 int main.foo3(int[], int) [0x5f76f906f9ac]
d/main.d:8 int main.foo4(int[], int) [0x5f76f906f9d8]
d/main.d:9 int main.foo5(int[], int) [0x5f76f906fa01]
d/main.d:10 int main.foo6(int[], int) [0x5f76f906fa38]
d/main.d:14 _Dmain [0x5f76f906fa64]
